{
  "results": [
    {
      "packageInfo": {
        "name": "Django",
        "version": "2.2.0",
        "ecosystem": "PyPI"
      },
      "vulnerabilities": [
        {
          "id": "GHSA-p64x-8rxw-9fxq",
          "summary": "Django has Uncontrolled Resource Consumption via cached header",
          "details": "An issue was discovered in Django 2.2 before 2.2.28, 3.2 before 3.2.13, and 4.0 before 4.0.4. The Trunc() and Extract() database functions are subject to SQL injection if untrusted data is used as a kind/lookup_name value.",
          "aliases": [
            "CVE-2022-28346",
            "GHSA-p64x-8rxw-9fxq"
          ],
          "modified": "2022-04-12T00:00:00Z",
          "published": "2022-04-11T00:00:00Z",
          "database_specific": {
            "severity": "HIGH",
            "cwe_ids": [
              "CWE-89",
              "CWE-1321"
            ]
          },
          "references": [
            {
              "type": "ADVISORY",
              "url": "https://nvd.nist.gov/vuln/detail/CVE-2022-28346"
            },
            {
              "type": "WEB",
              "url": "https://docs.djangoproject.com/en/4.0/releases/security/"
            }
          ]
        },
        {
          "id": "GHSA-2hrw-hx67-34x6",
          "summary": "Django Uncontrolled Resource Consumption",
          "details": "In Django 2.2 before 2.2.25, 3.1 before 3.1.14, and 3.2 before 3.2.10, HTTP requests for certain URLs can lead to a regular expression denial of service (ReDoS) via catastrophic backtracking.",
          "aliases": [
            "CVE-2021-44420",
            "GHSA-2hrw-hx67-34x6"
          ],
          "modified": "2021-12-07T00:00:00Z",
          "published": "2021-12-07T00:00:00Z",
          "database_specific": {
            "severity": "MEDIUM",
            "cwe_ids": [
              "CWE-400",
              "CWE-1333",
              "CWE-730"
            ]
          },
          "references": [
            {
              "type": "ADVISORY",
              "url": "https://nvd.nist.gov/vuln/detail/CVE-2021-44420"
            }
          ]
        }
      ]
    },
    {
      "packageInfo": {
        "name": "pyyaml",
        "version": "5.1",
        "ecosystem": "PyPI"
      },
      "vulnerabilities": [
        {
          "id": "GHSA-8q59-q68h-6hv4",
          "summary": "PyYAML vulnerable to Arbitrary Code Execution",
          "details": "A vulnerability was discovered in the PyYAML library in versions before 5.4, where it is susceptible to arbitrary code execution when it processes untrusted YAML files through the full_load method or with the FullLoader loader.",
          "aliases": [
            "CVE-2020-14343",
            "GHSA-8q59-q68h-6hv4"
          ],
          "modified": "2020-07-22T00:00:00Z",
          "published": "2020-07-22T00:00:00Z",
          "database_specific": {
            "severity": "CRITICAL",
            "cwe_ids": [
              "CWE-20",
              "CWE-94"
            ]
          },
          "references": [
            {
              "type": "ADVISORY",
              "url": "https://nvd.nist.gov/vuln/detail/CVE-2020-14343"
            },
            {
              "type": "WEB",
              "url": "https://github.com/yaml/pyyaml/pull/386"
            }
          ]
        }
      ]
    }
  ]
}
